---
comments: true
---

在Go语言中，异常处理采用的是错误值（error values）和延迟（defer）机制，而不是像其他语言（如Java或Python）那样使用传统的异常处理机制（try-catch）。

### 错误值（Error Values）

在Go语言中，函数通常会返回一个额外的错误值，通常是 `error` 类型。通过检查这个错误值来判断函数是否执行成功，并处理可能的错误情况。

```go
package main

import (
    "errors"
    "fmt"
)

// 定义一个函数，模拟文件操作，返回一个 error 值
func readFile(filename string) ([]byte, error) {
    // 模拟打开文件失败的情况
    if filename == "" {
        return nil, errors.New("filename cannot be empty")
    }
    
    // 模拟读取文件内容
    content := []byte("File content")
    return content, nil
}

func main() {
    content, err := readFile("example.txt")
    if err != nil {
        fmt.Println("Error reading file:", err)
        return // 可以在此处处理错误或者直接返回
    }

    fmt.Println("File content:", string(content))
}
```

在上面的例子中，`readFile` 函数返回两个值：文件内容和一个 `error`。在 `main` 函数中，我们通过检查 `err` 来判断文件读取是否成功。如果 `err` 不为 `nil`，表示发生了错误，可以进行相应的错误处理。

### 延迟（defer）机制

Go语言中的延迟（defer）机制可以用于确保一些清理操作在函数执行完毕后执行，无论函数是通过正常返回还是发生了错误。

```go
package main

import (
    "fmt"
    "os"
)

func main() {
    file, err := os.Open("example.txt")
    if err != nil {
        fmt.Println("Error opening file:", err)
        return
    }
    defer file.Close() // 确保在函数返回时关闭文件

    // 读取文件内容并进行处理
    // ...
}
```

在上面的例子中，`defer file.Close()` 确保了在 `main` 函数返回之前，无论在哪个地方退出函数，`file.Close()` 都会被调用来关闭文件。

### panic 和 recover

除了错误值和延迟机制外，Go语言还提供了 `panic` 和 `recover` 机制，用于处理更严重的错误情况。`panic` 类似于传统语言中的异常，用于不可恢复的错误，而 `recover` 用于从 `panic` 中恢复。

```go
package main

import "fmt"

func main() {
    defer func() {
        if err := recover(); err != nil {
            fmt.Println("Recovered from panic:", err)
        }
    }()

    panic("Something bad happened") // 这里会引发 panic

    fmt.Println("This line will not be reached")
}
```

在上面的例子中，`recover` 函数用于捕获由 `panic` 引发的错误，并在函数内部进行处理。但是，建议只在必要时使用 `panic` 和 `recover`，正常的错误处理应该通过错误值和延迟来实现。

### 总结

在Go语言中，异常处理主要通过错误值和延迟机制来实现。错误值用于表示函数执行过程中的错误，而延迟机制用于确保清理操作在函数退出时执行。对于更严重的错误，可以使用 `panic` 和 `recover` 机制，但应该谨慎使用，避免滥用。